[2025-04-06 19:48:58 +0000] [15950] [ERROR] Exception in worker process
Traceback (most recent call last):
  File "/home/runner/workspace/.pythonlibs/lib/python3.11/site-packages/gunicorn/arbiter.py", line 608, in spawn_worker
    worker.init_process()
  File "/home/runner/workspace/.pythonlibs/lib/python3.11/site-packages/gunicorn/workers/base.py", line 135, in init_process
    self.load_wsgi()
  File "/home/runner/workspace/.pythonlibs/lib/python3.11/site-packages/gunicorn/workers/base.py", line 147, in load_wsgi
    self.wsgi = self.app.wsgi()
                ^^^^^^^^^^^^^^^
  File "/home/runner/workspace/.pythonlibs/lib/python3.11/site-packages/gunicorn/app/base.py", line 66, in wsgi
    self.callable = self.load()
                    ^^^^^^^^^^^
  File "/home/runner/workspace/.pythonlibs/lib/python3.11/site-packages/gunicorn/app/wsgiapp.py", line 57, in load
    return self.load_wsgiapp()
           ^^^^^^^^^^^^^^^^^^^
  File "/home/runner/workspace/.pythonlibs/lib/python3.11/site-packages/gunicorn/app/wsgiapp.py", line 47, in load_wsgiapp
    return util.import_app(self.app_uri)
           ^^^^^^^^^^^^^^^^^^^^^^^^^^^^^
  File "/home/runner/workspace/.pythonlibs/lib/python3.11/site-packages/gunicorn/util.py", line 370, in import_app
    mod = importlib.import_module(module)
          ^^^^^^^^^^^^^^^^^^^^^^^^^^^^^^^
  File "/nix/store/clx0mcir7qw8zk36zbr4jra789g3knf6-python3-3.11.10/lib/python3.11/importlib/__init__.py", line 126, in import_module
    return _bootstrap._gcd_import(name[level:], package, level)
           ^^^^^^^^^^^^^^^^^^^^^^^^^^^^^^^^^^^^^^^^^^^^^^^^^^^^
  File "<frozen importlib._bootstrap>", line 1204, in _gcd_import
  File "<frozen importlib._bootstrap>", line 1176, in _find_and_load
  File "<frozen importlib._bootstrap>", line 1147, in _find_and_load_unlocked
  File "<frozen importlib._bootstrap>", line 690, in _load_unlocked
  File "<frozen importlib._bootstrap_external>", line 940, in exec_module
  File "<frozen importlib._bootstrap>", line 241, in _call_with_frames_removed
  File "/home/runner/workspace/main.py", line 2, in <module>
    from scraper.scraper import scrape_page
  File "/home/runner/workspace/scraper/scraper.py", line 16, in <module>
    class AsyncScraper:
  File "/home/runner/workspace/scraper/scraper.py", line 17, in AsyncScraper
    def __init__(self, concurrency_limit: int = SCRAPER_CONCURRENCY_LIMIT):
                                                ^^^^^^^^^^^^^^^^^^^^^^^^^
NameError: name 'SCRAPER_CONCURRENCY_LIMIT' is not defined
[2025-04-06 19:48:58 +0000] [15950] [INFO] Worker exiting (pid: 15950)
[2025-04-06 19:48:58 +0000] [15951] [ERROR] Exception in worker process
Traceback (most recent call last):
  File "/home/runner/workspace/.pythonlibs/lib/python3.11/site-packages/gunicorn/arbiter.py", line 608, in spawn_worker
    worker.init_process()
  File "/home/runner/workspace/.pythonlibs/lib/python3.11/site-packages/gunicorn/workers/base.py", line 135, in init_process
    self.load_wsgi()
  File "/home/runner/workspace/.pythonlibs/lib/python3.11/site-packages/gunicorn/workers/base.py", line 147, in load_wsgi
    self.wsgi = self.app.wsgi()
                ^^^^^^^^^^^^^^^
  File "/home/runner/workspace/.pythonlibs/lib/python3.11/site-packages/gunicorn/app/base.py", line 66, in wsgi
    self.callable = self.load()
                    ^^^^^^^^^^^
  File "/home/runner/workspace/.pythonlibs/lib/python3.11/site-packages/gunicorn/app/wsgiapp.py", line 57, in load
    return self.load_wsgiapp()
           ^^^^^^^^^^^^^^^^^^^
  File "/home/runner/workspace/.pythonlibs/lib/python3.11/site-packages/gunicorn/app/wsgiapp.py", line 47, in load_wsgiapp
    return util.import_app(self.app_uri)
           ^^^^^^^^^^^^^^^^^^^^^^^^^^^^^
  File "/home/runner/workspace/.pythonlibs/lib/python3.11/site-packages/gunicorn/util.py", line 370, in import_app
    mod = importlib.import_module(module)
          ^^^^^^^^^^^^^^^^^^^^^^^^^^^^^^^
  File "/nix/store/clx0mcir7qw8zk36zbr4jra789g3knf6-python3-3.11.10/lib/python3.11/importlib/__init__.py", line 126, in import_module
    return _bootstrap._gcd_import(name[level:], package, level)
           ^^^^^^^^^^^^^^^^^^^^^^^^^^^^^^^^^^^^^^^^^^^^^^^^^^^^
  File "<frozen importlib._bootstrap>", line 1204, in _gcd_import
  File "<frozen importlib._bootstrap>", line 1176, in _find_and_load
  File "<frozen importlib._bootstrap>", line 1147, in _find_and_load_unlocked
  File "<frozen importlib._bootstrap>", line 690, in _load_unlocked
  File "<frozen importlib._bootstrap_external>", line 940, in exec_module
  File "<frozen importlib._bootstrap>", line 241, in _call_with_frames_removed
  File "/home/runner/workspace/main.py", line 2, in <module>
    from scraper.scraper import scrape_page
  File "/home/runner/workspace/scraper/scraper.py", line 16, in <module>
    class AsyncScraper:
  File "/home/runner/workspace/scraper/scraper.py", line 17, in AsyncScraper
    def __init__(self, concurrency_limit: int = SCRAPER_CONCURRENCY_LIMIT):
                                                ^^^^^^^^^^^^^^^^^^^^^^^^^
NameError: name 'SCRAPER_CONCURRENCY_LIMIT' is not defined
[2025-04-06 19:48:58 +0000] [15951] [INFO] Worker exiting (pid: 15951)
[2025-04-06 19:48:58 +0000] [15938] [INFO] Handling signal: winch
[2025-04-06 19:48:58 +0000] [15953] [ERROR] Exception in worker process
Traceback (most recent call last):
  File "/home/runner/workspace/.pythonlibs/lib/python3.11/site-packages/gunicorn/arbiter.py", line 608, in spawn_worker
    worker.init_process()
  File "/home/runner/workspace/.pythonlibs/lib/python3.11/site-packages/gunicorn/workers/base.py", line 135, in init_process
    self.load_wsgi()
  File "/home/runner/workspace/.pythonlibs/lib/python3.11/site-packages/gunicorn/workers/base.py", line 147, in load_wsgi
    self.wsgi = self.app.wsgi()
                ^^^^^^^^^^^^^^^
  File "/home/runner/workspace/.pythonlibs/lib/python3.11/site-packages/gunicorn/app/base.py", line 66, in wsgi
    self.callable = self.load()
                    ^^^^^^^^^^^
  File "/home/runner/workspace/.pythonlibs/lib/python3.11/site-packages/gunicorn/app/wsgiapp.py", line 57, in load
    return self.load_wsgiapp()
           ^^^^^^^^^^^^^^^^^^^
  File "/home/runner/workspace/.pythonlibs/lib/python3.11/site-packages/gunicorn/app/wsgiapp.py", line 47, in load_wsgiapp
    return util.import_app(self.app_uri)
           ^^^^^^^^^^^^^^^^^^^^^^^^^^^^^
  File "/home/runner/workspace/.pythonlibs/lib/python3.11/site-packages/gunicorn/util.py", line 370, in import_app
    mod = importlib.import_module(module)
          ^^^^^^^^^^^^^^^^^^^^^^^^^^^^^^^
  File "/nix/store/clx0mcir7qw8zk36zbr4jra789g3knf6-python3-3.11.10/lib/python3.11/importlib/__init__.py", line 126, in import_module
    return _bootstrap._gcd_import(name[level:], package, level)
           ^^^^^^^^^^^^^^^^^^^^^^^^^^^^^^^^^^^^^^^^^^^^^^^^^^^^
  File "<frozen importlib._bootstrap>", line 1204, in _gcd_import
  File "<frozen importlib._bootstrap>", line 1176, in _find_and_load
  File "<frozen importlib._bootstrap>", line 1147, in _find_and_load_unlocked
  File "<frozen importlib._bootstrap>", line 690, in _load_unlocked
  File "<frozen importlib._bootstrap_external>", line 940, in exec_module
  File "<frozen importlib._bootstrap>", line 241, in _call_with_frames_removed
  File "/home/runner/workspace/main.py", line 2, in <module>
    from scraper.scraper import scrape_page
  File "/home/runner/workspace/scraper/scraper.py", line 16, in <module>
    class AsyncScraper:
  File "/home/runner/workspace/scraper/scraper.py", line 17, in AsyncScraper
    def __init__(self, concurrency_limit: int = SCRAPER_CONCURRENCY_LIMIT):
                                                ^^^^^^^^^^^^^^^^^^^^^^^^^
NameError: name 'SCRAPER_CONCURRENCY_LIMIT' is not defined
[2025-04-06 19:48:58 +0000] [15953] [INFO] Worker exiting (pid: 15953)
[2025-04-06 19:48:58 +0000] [15938] [ERROR] Worker (pid:15950) exited with code 3
[2025-04-06 19:48:58 +0000] [15938] [ERROR] Worker (pid:15951) was sent SIGTERM!
[2025-04-06 19:48:58 +0000] [15938] [ERROR] Worker (pid:15953) was sent SIGTERM!
[2025-04-06 19:48:58 +0000] [15952] [ERROR] Exception in worker process
Traceback (most recent call last):
  File "/home/runner/workspace/.pythonlibs/lib/python3.11/site-packages/gunicorn/arbiter.py", line 608, in spawn_worker
    worker.init_process()
  File "/home/runner/workspace/.pythonlibs/lib/python3.11/site-packages/gunicorn/workers/base.py", line 135, in init_process
    self.load_wsgi()
  File "/home/runner/workspace/.pythonlibs/lib/python3.11/site-packages/gunicorn/workers/base.py", line 147, in load_wsgi
    self.wsgi = self.app.wsgi()
                ^^^^^^^^^^^^^^^
  File "/home/runner/workspace/.pythonlibs/lib/python3.11/site-packages/gunicorn/app/base.py", line 66, in wsgi
    self.callable = self.load()
                    ^^^^^^^^^^^
  File "/home/runner/workspace/.pythonlibs/lib/python3.11/site-packages/gunicorn/app/wsgiapp.py", line 57, in load
    return self.load_wsgiapp()
           ^^^^^^^^^^^^^^^^^^^
  File "/home/runner/workspace/.pythonlibs/lib/python3.11/site-packages/gunicorn/app/wsgiapp.py", line 47, in load_wsgiapp
    return util.import_app(self.app_uri)
           ^^^^^^^^^^^^^^^^^^^^^^^^^^^^^
  File "/home/runner/workspace/.pythonlibs/lib/python3.11/site-packages/gunicorn/util.py", line 370, in import_app
    mod = importlib.import_module(module)
          ^^^^^^^^^^^^^^^^^^^^^^^^^^^^^^^
  File "/nix/store/clx0mcir7qw8zk36zbr4jra789g3knf6-python3-3.11.10/lib/python3.11/importlib/__init__.py", line 126, in import_module
    return _bootstrap._gcd_import(name[level:], package, level)
           ^^^^^^^^^^^^^^^^^^^^^^^^^^^^^^^^^^^^^^^^^^^^^^^^^^^^
  File "<frozen importlib._bootstrap>", line 1204, in _gcd_import
  File "<frozen importlib._bootstrap>", line 1176, in _find_and_load
  File "<frozen importlib._bootstrap>", line 1147, in _find_and_load_unlocked
  File "<frozen importlib._bootstrap>", line 690, in _load_unlocked
  File "<frozen importlib._bootstrap_external>", line 940, in exec_module
  File "<frozen importlib._bootstrap>", line 241, in _call_with_frames_removed
  File "/home/runner/workspace/main.py", line 2, in <module>
    from scraper.scraper import scrape_page
  File "/home/runner/workspace/scraper/scraper.py", line 16, in <module>
    class AsyncScraper:
  File "/home/runner/workspace/scraper/scraper.py", line 17, in AsyncScraper
    def __init__(self, concurrency_limit: int = SCRAPER_CONCURRENCY_LIMIT):
                                                ^^^^^^^^^^^^^^^^^^^^^^^^^
NameError: name 'SCRAPER_CONCURRENCY_LIMIT' is not defined
[2025-04-06 19:48:58 +0000] [15952] [INFO] Worker exiting (pid: 15952)
[2025-04-06 19:48:58 +0000] [15938] [ERROR] Worker (pid:15952) exited with code 3
Traceback (most recent call last):
  File "/home/runner/workspace/.pythonlibs/lib/python3.11/site-packages/gunicorn/arbiter.py", line 208, in run
    self.sleep()
  File "/home/runner/workspace/.pythonlibs/lib/python3.11/site-packages/gunicorn/arbiter.py", line 359, in sleep
    ready = select.select([self.PIPE[0]], [], [], 1.0)
            ^^^^^^^^^^^^^^^^^^^^^^^^^^^^^^^^^^^^^^^^^^
  File "/home/runner/workspace/.pythonlibs/lib/python3.11/site-packages/gunicorn/arbiter.py", line 241, in handle_chld
    self.reap_workers()
  File "/home/runner/workspace/.pythonlibs/lib/python3.11/site-packages/gunicorn/arbiter.py", line 529, in reap_workers
    raise HaltServer(reason, self.WORKER_BOOT_ERROR)
gunicorn.errors.HaltServer: <HaltServer 'Worker failed to boot.' 3>

During handling of the above exception, another exception occurred:

Traceback (most recent call last):
  File "/home/runner/workspace/.pythonlibs/bin/gunicorn", line 8, in <module>
    sys.exit(run())
             ^^^^^
  File "/home/runner/workspace/.pythonlibs/lib/python3.11/site-packages/gunicorn/app/wsgiapp.py", line 66, in run
    WSGIApplication("%(prog)s [OPTIONS] [APP_MODULE]", prog=prog).run()
  File "/home/runner/workspace/.pythonlibs/lib/python3.11/site-packages/gunicorn/app/base.py", line 235, in run
    super().run()
  File "/home/runner/workspace/.pythonlibs/lib/python3.11/site-packages/gunicorn/app/base.py", line 71, in run
    Arbiter(self).run()
  File "/home/runner/workspace/.pythonlibs/lib/python3.11/site-packages/gunicorn/arbiter.py", line 228, in run
    self.halt(reason=inst.reason, exit_status=inst.exit_status)
  File "/home/runner/workspace/.pythonlibs/lib/python3.11/site-packages/gunicorn/arbiter.py", line 341, in halt
    self.stop()
  File "/home/runner/workspace/.pythonlibs/lib/python3.11/site-packages/gunicorn/arbiter.py", line 395, in stop
    time.sleep(0.1)
  File "/home/runner/workspace/.pythonlibs/lib/python3.11/site-packages/gunicorn/arbiter.py", line 241, in handle_chld
    self.reap_workers()
  File "/home/runner/workspace/.pythonlibs/lib/python3.11/site-packages/gunicorn/arbiter.py", line 529, in reap_workers
    raise HaltServer(reason, self.WORKER_BOOT_ERROR)
gunicorn.errors.HaltServer: <HaltServer 'Worker failed to boot.' 3>